Workbook

Sheet Read Me
B1: Medical HRMS & Jameah — Task Tracker
B2: Al-Riyada College for Health Sciences · last updated 23 Oct 2026
B4: What this workbook is
B5: One place to see what has been done on Medical HRMS (HR system) and Jameah (the Ministry data system), what is being done now, and what is still pending.
B6: It continues the 1 Oct 2026 tracker (HRM_TASK_TRACKER.md / .csv): tasks HR-01 to HR-32 keep their IDs and are updated; HR-33 onwards and JM-01 onwards are new.
B8: Sheets
B9: Summary | C9: Counts by status, workstream and date. Updates by itself when you change a status in Tasks.
B10: Tasks | C10: Every task: when it was done, status, owner (who leads it: Abdul Hakeem for all development), assigned to (who the task is given to), evidence and the next step. Filter on any column.
B11: Bugs | C11: Every bug found during testing, its cause, the fix and how it was verified.
B12: Decisions | C12: Questions only the college, the Ministry or another team can answer. Yellow columns are for the answer.
B13: Change Log | C13: Every change, newest first, with its date and the items it touched.
B15: Status values
B16: Done | C16: Built and tested.
B17: Done – client UAT pending | C17: Built and tested by the team; waiting for HR/client acceptance testing.
B18: In progress | C18: Being worked on.
B19: Pending – decision needed | C19: Waiting for an answer (see Decisions).
B20: Pending – data / setup | C20: Code is ready; needs data entry or server setup.
B21: Pending – development | C21: Not built yet.
B22: Pending – other team | C22: Needs Finance, the server admin or another party outside the HRMS team.
B23: Planned | C23: Agreed for later; not started.
B25: Priority
B26: Critical | C26: Blocks go-live or the Ministry data: do first.
B27: High | C27: Needed for UAT / go-live.
B28: Medium | C28: Needed; can follow go-live.
B29: Low | C29: Tidy-up or nice to have.
B31: How to update
B32: Every change: update the row (status, evidence, next step) and its 'Last updated' date, and add a dated line to the Change Log. The same goes for the Checklist and the Test Cases workbook.
B33: Developers: edit project_tracking/source/*.py (data, dates in row_dates.py, changelog.py) and run python3 project_tracking/source/build_all.py - all three workbooks are rebuilt.
B35: Sources
B36: HRM_TASK_TRACKER.md/.csv, HRM_UAT_SCENARIOS.md, HRM_APPROVAL_MATRIX.md, JAMEAH_HRMS_* documents, MINISTRY_FIELD_MAPPING.html, Ministry schema V0.1, git history of medical_hrms (phpdevpro/edu-alriyada-hrm), test runs of 19–21 Oct 2026.
B37: Companion files in the same project_tracking folder: Medical_HRMS_Jameah_Checklist.xlsx (what is left to check or decide) and Medical_HRMS_Jameah_Test_Cases.xlsx (for the testing team).

Sheet Summary
A1: Summary
A2: Counts are formulas over the Tasks and Bugs sheets. As of 23 Oct 2026.
A4: Tasks by status | B4: Tasks
A5: Done | B5: =COUNTIF(Tasks!$E$2:$E$294,A5)
A6: Done – client UAT pending | B6: =COUNTIF(Tasks!$E$2:$E$294,A6)
A7: In progress | B7: =COUNTIF(Tasks!$E$2:$E$294,A7)
A8: Pending – decision needed | B8: =COUNTIF(Tasks!$E$2:$E$294,A8)
A9: Pending – data / setup | B9: =COUNTIF(Tasks!$E$2:$E$294,A9)
A10: Pending – development | B10: =COUNTIF(Tasks!$E$2:$E$294,A10)
A11: Pending – other team | B11: =COUNTIF(Tasks!$E$2:$E$294,A11)
A12: Planned | B12: =COUNTIF(Tasks!$E$2:$E$294,A12)
A13: Total tasks | B13: =SUM(B5:B12)
A15: Medical HRMS vs Jameah | B15: Done (both Done statuses) | C15: Open (everything else) | D15: Total
A16: Medical HRMS (HR-…) | B16: =COUNTIFS(Tasks!$A$2:$A$294,"HR-*",Tasks!$E$2:$E$294,"Done")+COUNTIFS(Tasks!$A$2:$A$294,"HR-*",Tasks!$E$2:$E$294,"Done – client UAT pending") | C16: =D16-B16 | D16: =COUNTIF(Tasks!$A$2:$A$294,"HR-*")
A17: Jameah (JM-…) | B17: =COUNTIFS(Tasks!$A$2:$A$294,"JM-*",Tasks!$E$2:$E$294,"Done")+COUNTIFS(Tasks!$A$2:$A$294,"JM-*",Tasks!$E$2:$E$294,"Done – client UAT pending") | C17: =D17-B17 | D17: =COUNTIF(Tasks!$A$2:$A$294,"JM-*")
A19: Work done by date | B19: Tasks
A20: Earlier (May – 5 Oct 2026) | B20: =COUNTIF(Tasks!$D$2:$D$294,"Earlier (May – 5 Oct 2026)")
A21: 19 Oct 2026 | B21: =COUNTIF(Tasks!$D$2:$D$294,"19 Oct 2026")
A22: 20 Oct 2026 | B22: =COUNTIF(Tasks!$D$2:$D$294,"20 Oct 2026")
A23: 21 Oct 2026 | B23: =COUNTIF(Tasks!$D$2:$D$294,"21 Oct 2026")
A24: 22 Oct 2026 | B24: =COUNTIF(Tasks!$D$2:$D$294,"22 Oct 2026")
A25: 23 Oct 2026 | B25: =COUNTIF(Tasks!$D$2:$D$294,"23 Oct 2026")
A26: — (not done yet) | B26: =COUNTIF(Tasks!$D$2:$D$294,"—")
A28: Workstream | B28: Done | C28: Done – client UAT pending | D28: In progress | E28: Pending – decision needed | F28: Pending – data / setup | G28: Pending – development | H28: Pending – other team | I28: Planned | J28: Total
A29: Foundation | B29: =COUNTIFS(Tasks!$B$2:$B$294,$A29,Tasks!$E$2:$E$294,B$28) | C29: =COUNTIFS(Tasks!$B$2:$B$294,$A29,Tasks!$E$2:$E$294,C$28) | D29: =COUNTIFS(Tasks!$B$2:$B$294,$A29,Tasks!$E$2:$E$294,D$28) | E29: =COUNTIFS(Tasks!$B$2:$B$294,$A29,Tasks!$E$2:$E$294,E$28) | F29: =COUNTIFS(Tasks!$B$2:$B$294,$A29,Tasks!$E$2:$E$294,F$28) | G29: =COUNTIFS(Tasks!$B$2:$B$294,$A29,Tasks!$E$2:$E$294,G$28) | H29: =COUNTIFS(Tasks!$B$2:$B$294,$A29,Tasks!$E$2:$E$294,H$28) | I29: =COUNTIFS(Tasks!$B$2:$B$294,$A29,Tasks!$E$2:$E$294,I$28) | J29: =COUNTIF(Tasks!$B$2:$B$294,$A29)
A30: Master data | B30: =COUNTIFS(Tasks!$B$2:$B$294,$A30,Tasks!$E$2:$E$294,B$28) | C30: =COUNTIFS(Tasks!$B$2:$B$294,$A30,Tasks!$E$2:$E$294,C$28) | D30: =COUNTIFS(Tasks!$B$2:$B$294,$A30,Tasks!$E$2:$E$294,D$28) | E30: =COUNTIFS(Tasks!$B$2:$B$294,$A30,Tasks!$E$2:$E$294,E$28) | F30: =COUNTIFS(Tasks!$B$2:$B$294,$A30,Tasks!$E$2:$E$294,F$28) | G30: =COUNTIFS(Tasks!$B$2:$B$294,$A30,Tasks!$E$2:$E$294,G$28) | H30: =COUNTIFS(Tasks!$B$2:$B$294,$A30,Tasks!$E$2:$E$294,H$28) | I30: =COUNTIFS(Tasks!$B$2:$B$294,$A30,Tasks!$E$2:$E$294,I$28) | J30: =COUNTIF(Tasks!$B$2:$B$294,$A30)
A31: Registration | B31: =COUNTIFS(Tasks!$B$2:$B$294,$A31,Tasks!$E$2:$E$294,B$28) | C31: =COUNTIFS(Tasks!$B$2:$B$294,$A31,Tasks!$E$2:$E$294,C$28) | D31: =COUNTIFS(Tasks!$B$2:$B$294,$A31,Tasks!$E$2:$E$294,D$28) | E31: =COUNTIFS(Tasks!$B$2:$B$294,$A31,Tasks!$E$2:$E$294,E$28) | F31: =COUNTIFS(Tasks!$B$2:$B$294,$A31,Tasks!$E$2:$E$294,F$28) | G31: =COUNTIFS(Tasks!$B$2:$B$294,$A31,Tasks!$E$2:$E$294,G$28) | H31: =COUNTIFS(Tasks!$B$2:$B$294,$A31,Tasks!$E$2:$E$294,H$28) | I31: =COUNTIFS(Tasks!$B$2:$B$294,$A31,Tasks!$E$2:$E$294,I$28) | J31: =COUNTIF(Tasks!$B$2:$B$294,$A31)
A32: Recruitment | B32: =COUNTIFS(Tasks!$B$2:$B$294,$A32,Tasks!$E$2:$E$294,B$28) | C32: =COUNTIFS(Tasks!$B$2:$B$294,$A32,Tasks!$E$2:$E$294,C$28) | D32: =COUNTIFS(Tasks!$B$2:$B$294,$A32,Tasks!$E$2:$E$294,D$28) | E32: =COUNTIFS(Tasks!$B$2:$B$294,$A32,Tasks!$E$2:$E$294,E$28) | F32: =COUNTIFS(Tasks!$B$2:$B$294,$A32,Tasks!$E$2:$E$294,F$28) | G32: =COUNTIFS(Tasks!$B$2:$B$294,$A32,Tasks!$E$2:$E$294,G$28) | H32: =COUNTIFS(Tasks!$B$2:$B$294,$A32,Tasks!$E$2:$E$294,H$28) | I32: =COUNTIFS(Tasks!$B$2:$B$294,$A32,Tasks!$E$2:$E$294,I$28) | J32: =COUNTIF(Tasks!$B$2:$B$294,$A32)
A33: HR dashboard | B33: =COUNTIFS(Tasks!$B$2:$B$294,$A33,Tasks!$E$2:$E$294,B$28) | C33: =COUNTIFS(Tasks!$B$2:$B$294,$A33,Tasks!$E$2:$E$294,C$28) | D33: =COUNTIFS(Tasks!$B$2:$B$294,$A33,Tasks!$E$2:$E$294,D$28) | E33: =COUNTIFS(Tasks!$B$2:$B$294,$A33,Tasks!$E$2:$E$294,E$28) | F33: =COUNTIFS(Tasks!$B$2:$B$294,$A33,Tasks!$E$2:$E$294,F$28) | G33: =COUNTIFS(Tasks!$B$2:$B$294,$A33,Tasks!$E$2:$E$294,G$28) | H33: =COUNTIFS(Tasks!$B$2:$B$294,$A33,Tasks!$E$2:$E$294,H$28) | I33: =COUNTIFS(Tasks!$B$2:$B$294,$A33,Tasks!$E$2:$E$294,I$28) | J33: =COUNTIF(Tasks!$B$2:$B$294,$A33)
A34: Self-service | B34: =COUNTIFS(Tasks!$B$2:$B$294,$A34,Tasks!$E$2:$E$294,B$28) | C34: =COUNTIFS(Tasks!$B$2:$B$294,$A34,Tasks!$E$2:$E$294,C$28) | D34: =COUNTIFS(Tasks!$B$2:$B$294,$A34,Tasks!$E$2:$E$294,D$28) | E34: =COUNTIFS(Tasks!$B$2:$B$294,$A34,Tasks!$E$2:$E$294,E$28) | F34: =COUNTIFS(Tasks!$B$2:$B$294,$A34,Tasks!$E$2:$E$294,F$28) | G34: =COUNTIFS(Tasks!$B$2:$B$294,$A34,Tasks!$E$2:$E$294,G$28) | H34: =COUNTIFS(Tasks!$B$2:$B$294,$A34,Tasks!$E$2:$E$294,H$28) | I34: =COUNTIFS(Tasks!$B$2:$B$294,$A34,Tasks!$E$2:$E$294,I$28) | J34: =COUNTIF(Tasks!$B$2:$B$294,$A34)
A35: Security | B35: =COUNTIFS(Tasks!$B$2:$B$294,$A35,Tasks!$E$2:$E$294,B$28) | C35: =COUNTIFS(Tasks!$B$2:$B$294,$A35,Tasks!$E$2:$E$294,C$28) | D35: =COUNTIFS(Tasks!$B$2:$B$294,$A35,Tasks!$E$2:$E$294,D$28) | E35: =COUNTIFS(Tasks!$B$2:$B$294,$A35,Tasks!$E$2:$E$294,E$28) | F35: =COUNTIFS(Tasks!$B$2:$B$294,$A35,Tasks!$E$2:$E$294,F$28) | G35: =COUNTIFS(Tasks!$B$2:$B$294,$A35,Tasks!$E$2:$E$294,G$28) | H35: =COUNTIFS(Tasks!$B$2:$B$294,$A35,Tasks!$E$2:$E$294,H$28) | I35: =COUNTIFS(Tasks!$B$2:$B$294,$A35,Tasks!$E$2:$E$294,I$28) | J35: =COUNTIF(Tasks!$B$2:$B$294,$A35)
A36: Leave | B36: =COUNTIFS(Tasks!$B$2:$B$294,$A36,Tasks!$E$2:$E$294,B$28) | C36: =COUNTIFS(Tasks!$B$2:$B$294,$A36,Tasks!$E$2:$E$294,C$28) | D36: =COUNTIFS(Tasks!$B$2:$B$294,$A36,Tasks!$E$2:$E$294,D$28) | E36: =COUNTIFS(Tasks!$B$2:$B$294,$A36,Tasks!$E$2:$E$294,E$28) | F36: =COUNTIFS(Tasks!$B$2:$B$294,$A36,Tasks!$E$2:$E$294,F$28) | G36: =COUNTIFS(Tasks!$B$2:$B$294,$A36,Tasks!$E$2:$E$294,G$28) | H36: =COUNTIFS(Tasks!$B$2:$B$294,$A36,Tasks!$E$2:$E$294,H$28) | I36: =COUNTIFS(Tasks!$B$2:$B$294,$A36,Tasks!$E$2:$E$294,I$28) | J36: =COUNTIF(Tasks!$B$2:$B$294,$A36)
A37: Approvals | B37: =COUNTIFS(Tasks!$B$2:$B$294,$A37,Tasks!$E$2:$E$294,B$28) | C37: =COUNTIFS(Tasks!$B$2:$B$294,$A37,Tasks!$E$2:$E$294,C$28) | D37: =COUNTIFS(Tasks!$B$2:$B$294,$A37,Tasks!$E$2:$E$294,D$28) | E37: =COUNTIFS(Tasks!$B$2:$B$294,$A37,Tasks!$E$2:$E$294,E$28) | F37: =COUNTIFS(Tasks!$B$2:$B$294,$A37,Tasks!$E$2:$E$294,F$28) | G37: =COUNTIFS(Tasks!$B$2:$B$294,$A37,Tasks!$E$2:$E$294,G$28) | H37: =COUNTIFS(Tasks!$B$2:$B$294,$A37,Tasks!$E$2:$E$294,H$28) | I37: =COUNTIFS(Tasks!$B$2:$B$294,$A37,Tasks!$E$2:$E$294,I$28) | J37: =COUNTIF(Tasks!$B$2:$B$294,$A37)
A38: Compliance | B38: =COUNTIFS(Tasks!$B$2:$B$294,$A38,Tasks!$E$2:$E$294,B$28) | C38: =COUNTIFS(Tasks!$B$2:$B$294,$A38,Tasks!$E$2:$E$294,C$28) | D38: =COUNTIFS(Tasks!$B$2:$B$294,$A38,Tasks!$E$2:$E$294,D$28) | E38: =COUNTIFS(Tasks!$B$2:$B$294,$A38,Tasks!$E$2:$E$294,E$28) | F38: =COUNTIFS(Tasks!$B$2:$B$294,$A38,Tasks!$E$2:$E$294,F$28) | G38: =COUNTIFS(Tasks!$B$2:$B$294,$A38,Tasks!$E$2:$E$294,G$28) | H38: =COUNTIFS(Tasks!$B$2:$B$294,$A38,Tasks!$E$2:$E$294,H$28) | I38: =COUNTIFS(Tasks!$B$2:$B$294,$A38,Tasks!$E$2:$E$294,I$28) | J38: =COUNTIF(Tasks!$B$2:$B$294,$A38)
A39: Integration | B39: =COUNTIFS(Tasks!$B$2:$B$294,$A39,Tasks!$E$2:$E$294,B$28) | C39: =COUNTIFS(Tasks!$B$2:$B$294,$A39,Tasks!$E$2:$E$294,C$28) | D39: =COUNTIFS(Tasks!$B$2:$B$294,$A39,Tasks!$E$2:$E$294,D$28) | E39: =COUNTIFS(Tasks!$B$2:$B$294,$A39,Tasks!$E$2:$E$294,E$28) | F39: =COUNTIFS(Tasks!$B$2:$B$294,$A39,Tasks!$E$2:$E$294,F$28) | G39: =COUNTIFS(Tasks!$B$2:$B$294,$A39,Tasks!$E$2:$E$294,G$28) | H39: =COUNTIFS(Tasks!$B$2:$B$294,$A39,Tasks!$E$2:$E$294,H$28) | I39: =COUNTIFS(Tasks!$B$2:$B$294,$A39,Tasks!$E$2:$E$294,I$28) | J39: =COUNTIF(Tasks!$B$2:$B$294,$A39)
A40: Payroll | B40: =COUNTIFS(Tasks!$B$2:$B$294,$A40,Tasks!$E$2:$E$294,B$28) | C40: =COUNTIFS(Tasks!$B$2:$B$294,$A40,Tasks!$E$2:$E$294,C$28) | D40: =COUNTIFS(Tasks!$B$2:$B$294,$A40,Tasks!$E$2:$E$294,D$28) | E40: =COUNTIFS(Tasks!$B$2:$B$294,$A40,Tasks!$E$2:$E$294,E$28) | F40: =COUNTIFS(Tasks!$B$2:$B$294,$A40,Tasks!$E$2:$E$294,F$28) | G40: =COUNTIFS(Tasks!$B$2:$B$294,$A40,Tasks!$E$2:$E$294,G$28) | H40: =COUNTIFS(Tasks!$B$2:$B$294,$A40,Tasks!$E$2:$E$294,H$28) | I40: =COUNTIFS(Tasks!$B$2:$B$294,$A40,Tasks!$E$2:$E$294,I$28) | J40: =COUNTIF(Tasks!$B$2:$B$294,$A40)
... A51: Jameah | B51: =COUNTIFS(Tasks!$B$2:$B$294,$A51,Tasks!$E$2:$E$294,B$28) | C51: =COUNTIFS(Tasks!$B$2:$B$294,$A51,Tasks!$E$2:$E$294,C$28) | D51: =COUNTIFS(Tasks!$B$2:$B$294,$A51,Tasks!$E$2:$E$294,D$28) | E51: =COUNTIFS(Tasks!$B$2:$B$294,$A51,Tasks!$E$2:$E$294,E$28) | F51: =COUNTIFS(Tasks!$B$2:$B$294,$A51,Tasks!$E$2:$E$294,F$28) | G51: =COUNTIFS(Tasks!$B$2:$B$294,$A51,Tasks!$E$2:$E$294,G$28) | H51: =COUNTIFS(Tasks!$B$2:$B$294,$A51,Tasks!$E$2:$E$294,H$28) | I51: =COUNTIFS(Tasks!$B$2:$B$294,$A51,Tasks!$E$2:$E$294,I$28) | J51: =COUNTIF(Tasks!$B$2:$B$294,$A51)
A53: Bugs | B53: Count
A54: Fixed | B54: =COUNTIF(Bugs!$H$2:$H$156,A54)
A55: Open | B55: =COUNTIF(Bugs!$H$2:$H$156,A55)
...

Sheet Tasks
A1: ID | B1: Workstream | C1: Task | D1: When done | E1: Status | F1: Owner | G1: Assigned to | H1: Priority | I1: Done so far / evidence | J1: Next step / pending | K1: Reference (commit / file) | L1: Last updated
A2: HR-01 | B2: Foundation | C2: Custom Medical HRMS app and setup scripts | D2: Earlier (May – 5 Oct 2026) | E2: Done | F2: Abdul Hakeem | G2: Abdul Hakeem | H2: Medium | I2: App, setup scripts and migration hooks exist. Migration re-run several times on 19–21 Oct without errors or duplicates; Ministry fields, permissions and Jameah views are created on every migrate. | J2: Run the same migration once on the production server. | K2: hooks.py; patches.txt | L2: 21 Oct 2026
A3: HR-02 | B3: Master data | C3: Ministry lookup codes and validation | D3: 19 Oct 2026 | E3: Done | F3: Abdul Hakeem | G3: Abdul Hakeem | H3: High | I3: 9,867 Ministry codes loaded from the Arabic and Translated workbooks, every code with Arabic and English names (before: 8,330 showed the code as their name). Loaded automatically on migrate. Demo codes remapped and removed. | J3: None. | K3: 277442b; ministry_codes.py; data/ministry_codes.csv | L3: 21 Oct 2026
A4: HR-03 | B4: Master data | C4: Institute hierarchy and facility records | D4: Earlier (May – 5 Oct 2026) | E4: Pending – data / setup | F4: HR | G4: HR | H4: Medium | I4: Branch, Agency, Deanery, College, Academic Department and Facility doctypes exist and are linked to Employee/Instructor. | J4: HR to enter the real hierarchy and confirm employee placement. | K4: create_institute_doctypes.py; create_facility_doctype.py | L4: 21 Oct 2026
A5: HR-04 | B5: Registration | C5: Job-level setup | D5: Earlier (May – 5 Oct 2026) | E5: In progress | F5: Abdul Hakeem | G5: Fathir | H5: Medium | I5: Assigned to Dinesh first (commits 2–5 Oct); now assigned to Fathir. | J5: Fathir to report the scope done and what remains. | K5: HRM_TASK_TRACKER.md | L5: 23 Oct 2026
A6: HR-05 | B6: Registration | C6: Employee registration | D6: 19 Oct 2026 | E6: In progress | F6: Abdul Hakeem | G6: Fathir | H6: High | I6: Ministry identity rules added (national ID 10 digits starting 1 for Saudis, Iqama 10 digits starting 2) and duplicates blocked (same identity number, home ID or job number). Mandatory Ministry fields enforced on save. | J6: Fathir (assigned) to confirm the remaining registration scope; complete the EMP-00001 demo record (HR-53). | K6: 1f88c78; ministry_lookup_validation.py | L6: 23 Oct 2026
A7: HR-06 | B7: Recruitment | C7: Job Applicant to Employee transfer | D7: 19 Oct 2026 | E7: Done – client UAT pending | F7: Abdul Hakeem | G7: Dinesh | H7: High | I7: Designed and built by Abdul Hakeem, with parts assigned to Dinesh; the form's UI is now assigned to Fathir (HR-70). Public application form -> Accept -> Create Employee tested in the browser on 19, 20 and 21 Oct. Creates Employee, login, Instructor / Academic Advisor / HOD records by role. Lost fields fixed on 20 Oct (HR-44). | J7: HR to run one real hire on the test site. | K7: job_application.py; 8390598 | L7: 23 Oct 2026
A8: HR-07 | B8: Registration | C8: Qualifications, experience and Ministry profile fields | D8: 20 Oct 2026 | E8: Done | F8: Abdul Hakeem | G8: Abdul Hakeem | H8: High | I8: Jameah child tables (qualifications, academic experience, previous experience, training, awards, publications) on Employee. 'Appreciation' fixed to use the Ministry grade list on 20 Oct. These feed the Jameah Employee views. | J8: None. | K8: setup_employee_ministry_expected_fields.py; d690cb7 | L8: 21 Oct 2026
A9: HR-08 | B9: HR dashboard | C9: HR dashboard and leave-management shortcuts | D9: 20 Oct 2026 | E9: Done – client UAT pending | F9: Abdul Hakeem | G9: Abdul Hakeem | H9: High | I9: Every dashboard link opens without an error (browser test HRD-03, 21 Oct). Counts fixed on 19 Oct. Academic Presence and Jameah sections added. 22 Oct: Leave section - setup check per company, Sick Leave card, daily leave counts and the yearly setup steps in order (LV-06). | J9: HR UAT. | K9: page/hr_dashboard | L9: 22 Oct 2026
A10: HR-09 | B10: Self-service | C10: Employee self-service dashboard | D10: 20 Oct 2026 | E10: Done – client UAT pending | F10: Abdul Hakeem | G10: Abdul Hakeem | H10: High | I10: All request types, leave request, details view and counters tested in the browser (ESS-01..17). 22 Oct: 11 cards, the three leave cards first (Leave Plan, Leave Application, Leave Return), and a My Leave panel that says what to do next (LV-01..05). | J10: Employee UAT, including on a phone. | K10: page/employee_dashboard | L10: 22 Oct 2026
A11: HR-10 | B11: HR dashboard | C11: Custom workspace styling | D11: Earlier (May – 5 Oct 2026) | E11: Done – client UAT pending | F11: Abdul Hakeem | G11: Abdul Hakeem | H11: Low | I11: Workspace renders (browser test HRD-04). | J11: Check long labels and mobile layout during UAT. | K11: public/css/workspace_theme.css | L11: 21 Oct 2026
A12: HR-11 | B12: Self-service | C12: Self-service in Instructor, HOD and other staff dashboards | D12: — | E12: Planned | F12: Abdul Hakeem | G12: Abdul Hakeem | H12: High | I12: Not started. Instructors with an Employee record can already use /app/employee-dashboard. | J12: Add the request and leave cards to the Instructor / HOD dashboards from Medical HRMS (page scripts in this app). | K12: HRM_TASK_TRACKER.md | L12: 23 Oct 2026
... A94: JM-17 | B94: Jameah | C94: Transcript GPA rounding at exact ties | D94: 21 Oct 2026 | E94: Done | F94: Abdul Hakeem | G94: Abdul Hakeem | H94: Low | I94: Resolved by the college's official GPA calculation (exact half-up rounding); the Ministry views use it (JM-18). | J94: None. | K94: Jameah report | L94: 23 Oct 2026

Sheet Bugs
A1: Bug ID | B1: Found on | C1: Area | D1: Problem | E1: Cause | F1: Fix | G1: Commit / task | H1: Status | I1: How verified | J1: Last updated
A2: B-01 | B2: 19 Oct 2026 | C2: Travel Request | D2: Every save crashed | E2: Validation read fields that don't exist | F2: Cost read from costings, checked on submit | G2: 91b7697 | H2: Fixed | I2: E2E 19 Oct | J2: 21 Oct 2026
A3: B-02 | B3: 19 Oct 2026 | C3: Approvals | D3: Finance approval impossible | E3: Hooks accepted only Finance Manager, which had no access | F3: Accept Finance Manager or Accounts Manager; grant access | G3: 91b7697 | H3: Fixed | I3: E2E 19 Oct | J3: 21 Oct 2026
A4: B-03 | B4: 19 Oct 2026 | C4: Return from Leave | D4: Employees could not send the request | E4: Clearance guard compared against the wrong default | F4: Compare with the Select's first option | G4: 91b7697 | H4: Fixed | I4: E2E APR-06 | J4: 21 Oct 2026
A5: B-04 | B5: 19 Oct 2026 | C5: Children Medical Allowance | D5: Every claim blocked, even drafts | E5: Unused Employee Grade requirement | F5: Requirement removed | G5: 91b7697 | H5: Fixed | I5: E2E ESS-12 | J5: 21 Oct 2026
A6: B-05 | B6: 19 Oct 2026 | C6: Medical License | D6: Employees could list everyone's licences | E6: No own-record rule | F6: Own-record permission rules | G6: 91b7697 | H6: Fixed | I6: E2E LIC-02 | J6: 21 Oct 2026
A7: B-06 | B7: 19 Oct 2026 | C7: HR Dashboard | D7: Return-from-leave count always 0 | E7: Doctype name casing | F7: Corrected | G7: 91b7697 | H7: Fixed | I7: E2E HRD-02 | J7: 21 Oct 2026
A8: B-07 | B8: 19 Oct 2026 | C8: Employee Dashboard | D8: Drafts counted as pending | E8: Status filter | F8: Drafts excluded | G8: 91b7697 | H8: Fixed | I8: E2E ESS-15 | J8: 21 Oct 2026
A9: B-08 | B9: 19 Oct 2026 | C9: Recruitment (security) | D9: A guest could obtain System Manager via the public form | E9: Role taken from the guest payload | F9: Hireable-role allow-list, server-controlled fields protected | G9: 0ab539e | H9: Fixed | I9: E2E REC-02 | J9: 21 Oct 2026
A10: B-09 | B10: 19 Oct 2026 | C10: Recruitment | D10: Academic hires landed on dashboards that couldn't find them | E10: Only an Instructor record was created | F10: Records per role (Advisor, HOD...) | G10: 8390598 | H10: Fixed | I10: E2E REC-03/04 | J10: 21 Oct 2026
A11: B-10 | B11: 19 Oct 2026 | C11: Ministry codes | D11: 8,330 codes showed the code as their name; no Arabic | E11: Importer read only the translated workbook | F11: Merge Arabic + translated workbooks | G11: 277442b | H11: Fixed | I11: Data check | J11: 21 Oct 2026
A12: B-11 | B12: 19 Oct 2026 | C12: Registration | D12: Home-country ID required for non-Saudis instead of the Kingdom ID | E12: Wrong rule | F12: Ministry identity rules | G12: 1f88c78 | H12: Fixed | I12: Unit + E2E EMP-05/06 | J12: 21 Oct 2026
... A56: B-27 | B56: 21 Oct 2026 | C56: Website | D56: Logo file missing (/files/rchs-logo.png) | E56: File not on this copy | F56: Check on the live server | G56: HR-54 | H56: Open – check server | I56: Error sweep | J56: 21 Oct 2026

Sheet Decisions
A1: ID | B1: Decision needed | C1: Who decides | D1: Options / recommendation | E1: Blocks tasks | F1: Answer (fill in) | G1: Answered on | H1: Last updated
A2: DEC-01 | B2: Which view and column names does the Jameah agent read: the HTML names or the Ministry schema V0.1 names? (The HTML also spells Faculty columns 'EnglishFourhtName' and 'Summury'; the views follow it exactly.) | C2: Ministry contact (Ms. Najah) | D2: Confirm with the Ministry; renaming is a small change. | E2: JM-09, go-live of Jameah | H2: 21 Oct 2026
A3: DEC-02 | B3: College code the Ministry assigned to RCHS (College Coding Guide) | C3: Academic Affairs | D3: From the Ministry licence; pick in Jameah Settings. | E3: JM-10 | H3: 21 Oct 2026
A4: DEC-03 | B4: Study type for regular and for bridging students | C4: Academic Affairs | D4: List includes 0 Total regularity, 7 Bridging. | E4: JM-10 | H4: 21 Oct 2026
A5: DEC-04 | B5: Program duration and unit | C5: Academic Affairs | D5: From the study plan. | E5: JM-10 | H5: 21 Oct 2026
A6: DEC-05 | B6: Campus city (Study Location City) | C6: Academic Affairs | D6: Ministry city code, e.g. 0202000 Jeddah Governorate if applicable. | E6: JM-10 | H6: 21 Oct 2026
A7: DEC-06 | B7: Ministry department and specialization for the nursing program | C7: Academic Affairs | D7: Candidates KL01 Nursing Sciences / KL03 Nursing. | E7: JM-11 | H7: 21 Oct 2026
A8: DEC-07 | B8: Ministry status for 'Internship' students (238) | C8: Academic Affairs | D8: Most likely 0 'restricted (enrolled)'. | E8: JM-11 | H8: 21 Oct 2026
A9: DEC-08 | B9: Accept 9-digit identity numbers? | C9: HR + Ministry contact | D9: Today exactly 10 digits for National ID / Iqama. | E9: HR-52 | H9: 21 Oct 2026
A10: DEC-09 | B10: Approver for each request step and the currency label (SAR) | C10: HR + Finance | D10: Update HRM_APPROVAL_MATRIX.md. | E10: HR-24 | H10: 21 Oct 2026
A11: DEC-10 | B11: Official holidays and carry-forward rules | C11: HR | D11: Needed for leave and presence. | E11: HR-23, HR-57 | H11: 21 Oct 2026
A12: DEC-11 | B12: Ministry credit hours: Registered = hours registered this term; Passed = earned + bridged plan hours (so Passed + Remaining = Required, as on the student dashboard). The transcript also shows a lifetime 'registered' total and bridging calc-hours. | C12: Academic Affairs | D12: Recommended as built; confirm with the Ministry definitions. | E12: JM-18 | H12: 21 Oct 2026
A13: DEC-12 | B13: Faculty sent to the Ministry: active Instructors only (as built), or also those marked Left? | C13: Academic Affairs | D13: Recommended: active only; former faculty would need end dates. | E13: JM-14 | H13: 21 Oct 2026
... A16: DEC-15 | B16: Students on Campus: keep one-hour slots (as built, 7:00-22:00) or count by the college's own teaching periods? The client's request says 'during each period'. | C16: HR (client) | D16: Review at the progress meeting; periods would need their start and end times. | E16: HR-38 | H16: 23 Oct 2026

Sheet Change Log
A1: Date | B1: Area | C1: Items | D1: What changed | E1: By
A2: 23 Oct 2026 | B2: Documentation | C2: HR-37, HR-38, DEC-15, CL-38 | D2: Academic Presence (HR requirements 1-4) checked against the client's request: all four are on the HR Dashboard and tested. The guides now say where each tab's data comes from, that Proctor Schedules stays empty until exam committees are entered (new Checklist CL-38), that Students on Campus counts by hour, and that after-4 PM times come from the timetable and class attendance until devices are connected. New decision DEC-15: hour slots or the college's own periods. | E2: Abdul Hakeem
A3: 23 Oct 2026 | B3: Documentation | C3: HR-74, B-54, B-55, TC-ESS-02, TC-ESS-04, TC-ESS-16, CL-37 | D3: Installation and Setup Guide (21 pages) and User Guide (30 pages) in PDF, with screenshots from the test site (QA data only); sources in docs/guides/src. Fixed while writing them: Remote Work Request duration and Permission Request hours were always 0 (now counted; reversed times refused; a patch fills in saved requests). Re-tested: 95/95 browser checks, 42 unit tests (0 failures), 0 file and 0 site problems, 29 server methods x 3 roles, no Error Log entries. | E3: Abdul Hakeem
A4: 23 Oct 2026 | B4: Project tracking | C4: All tasks; HR-04 - HR-06, HR-11, HR-12, HR-28 - HR-30, HR-48, HR-66, HR-70, HR-71, HR-73, JM-03, JM-06, JM-12, JM-13, JM-16, JM-17, B-26, B-34, CL-35 | D4: Owners corrected: Abdul Hakeem designed and built Medical HRMS and Jameah and leads every development task. New column 'Assigned to' (with a dropdown) shows who a task was given to: Dinesh (HR-06, and HR-04 at first), Fathir (HR-04, HR-05, HR-70), otherwise Abdul Hakeem; client-side tasks stay with HR, Academic Affairs, the Registrar or the server admin. Wording that credited others for this work removed. Status and Priority shown in clear colours in all three workbooks (Status, Priority, Result and Severity cells only), with a priority legend in the Read Me. | E4: Abdul Hakeem
A5: 23 Oct 2026 | B5: Project tracking | C5: HR-72, B-52, B-53 | D5: The three check scripts (files, site, server methods) now record their result in the Test Cases workbook (Last automated run: Pass, 23 Oct). The file check found a missing import in the site check; fixed. | E5: Abdul Hakeem
A6: 23 Oct 2026 | B6: Medical HRMS | C6: HR-58, HR-69, HR-71 - HR-73, B-45 - B-51, CL-01, CL-30, CL-34 - CL-36, TC-ERR-06 - TC-ERR-09, TC-SEC-10 | D6: Every branch merged into develop (ministry-lookup last; employee-applicant recorded as merged without its July files, as decided); develop is now the branch to test and deploy. Full check of every file and page (files, site, server methods by role, unit tests, browser suite with a sweep of every Medical HRMS doctype); checks kept in tests/checks. Fixed: stray files, outdated README and developer guide, QA setup race, refresh-lock test, Ministry code search. HR-69 corrected (employee counts were test hires). Result: 95/95 browser checks (error sweep: 116 pages for HR, 20 for employees), 37/37 unit tests, 23/23 Ministry views, 29 server methods x 3 roles, 0 file and 0 site problems, no Error Log entries. | E6: Abdul Hakeem
A7: 22 Oct 2026 | B7: Medical HRMS | C7: HR-58, HR-70, JM-05, JM-19, B-42 – B-44, TC-REC-13, TC-REC-14 | D7: develop (Fathir's job application update, PR #2) merged into feature/uat-2026-10-22; conflicts in job_application.py, job-application.html and ar.csv resolved keeping both sides; the Appreciation list restored and the work extension accepted again on the updated form (B-42, B-44); a migrate no longer fails when it overlaps the hourly Jameah refresh (B-43); test output removed from the repository. Re-tested: 95/95 browser checks, 37/37 unit tests, 23/23 Ministry views OK, no Error Log entries. Branch to test and deploy: feature/uat-2026-10-22. | E7: Abdul Hakeem
A8: 22 Oct 2026 | B8: Medical HRMS | C8: HR-08, HR-09, HR-19, HR-20, HR-22, HR-68, HR-69, B-36 – B-40, DEC-14, CL-28 – CL-33 | D8: Leave made one flow: Leave Plan (employees send it; manager and department head approve) -> Leave Application (only leave the employee holds, with the days left; Apply now from an approved plan) -> Leave Return (asked for when a leave ends; certificate and occupational health only after sick leave). Sick-leave types renamed in pay order (Sick Leave 1 / 2 / 3) by a migration patch. HR Portal Leave section: setup check per company, daily leave counts, yearly setup in order. Arabic for 114 new texts. 5 unit tests and 7 browser tests (LV-01 - LV-07); test cases TC-LV-09 - 17, TC-HRD-06/07. Real company Al Riyada College still needs its leave setup (HR-69). Branch to test and deploy: feature/uat-2026-10-22 (all work to date). | E8: Abdul Hakeem
A9: 22 Oct 2026 | B9: Testing | C9: HR-67, B-41 | D9: Browser test suite, QA data scripts and the results helper kept in the repository (tests/e2e); the QA scripts only run on a site named in QA_TEST_SITE. The QA reset no longer leaves the QA HR User without access to its own My Settings (test data only). The leave unit test now attaches a real test file, so it no longer writes 'Error Attaching File' to the Error Log. Full run 22 Oct: 95/95 browser checks, 36/36 unit tests, 23/23 Ministry views OK, no new Error Log entries. | E9: Abdul Hakeem
A10: 21 Oct 2026 | B10: Medical HRMS + Jameah | C10: HR-49, HR-50, HR-51, HR-65, JM-14, B-35, DEC-12, DEC-13 | D10: Report 'Employees Missing Ministry Data'; data sheet for non-academic staff (download, check, import); unused duplicate applicant Ministry fields removed; Create Employee dialog asks for every field the Employee form requires; Jameah Faculty views (8) built and verified (23 views in all). Arabic for the 46 new labels. Documents moved to the project_tracking folder; Checklist workbook added; dates on every row; HRM_TASK_TRACKER.md marked as superseded. | E10: Abdul Hakeem
A11: 21 Oct 2026 | B11: Medical HRMS | C11: HR-66 | D11: HR Portal and Employee Portal in the new college portal design (menu, top bar, EN/AR, dark mode); Arabic translations for these pages. | E11: Abdul Hakeem
A12: 21 Oct 2026 | B12: Medical HRMS + Jameah | C12: HR-12, HR-31, HR-32, HR-45, HR-46, HR-59 – HR-64, JM-17, JM-18, B-24 – B-34 | D12: End-to-end test round 3 with an error sweep of every page: fixes for the errors the client reported (non-Saudi employees, breadcrumb 'Not permitted', Cost Center pop-up, academic hire e-mail, Holiday List); HR login lands on the HR Dashboard; Ministry GPA and credit hours from the college's official calculation. Test Report, Test Cases and Task Tracker created. | E12: Abdul Hakeem
... A15: 1 Oct 2026 | B15: Medical HRMS | C15: HR-01 – HR-32 | D15: First HRM task tracker (HRM_TASK_TRACKER.md / .csv). | E15: Team
